Workbook

Sheet Lookup
A1: Template LEGACY cases S62A | B1: Field | C1: Data model | D1: Pre-application - DONE | E1: Application (Major) | F1: Application (Non Major) | G1: Notes S/S | H1: Horizon | I1: Notes Horizon
B2: Case reference | C2: Case reference | D2: Ref | E2: Ref | F2: Ref | H2: basic_data.CaseReference
A3: Case progress | B3: Pre-application status | C3: Status | D3: N/A | E3: N/A | F3: N/A | H3: N/A | I3: Manually override, will be Decision for most Horizon | J3: Should this be closed? -> yes
B4: Application Status | C4: Status | D4: N/A | E4: N/A | F4: N/A | H4: basic_data.Status
B5: Stage | C5: Stage | D5: N/A | E5: N/A | F5: N/A | H5: N/A | I5: Manually override, will be Decision for most Horizon
A6: Case type | B6: Application phase | C6: Application phase | D6: Set to be "Pre-application" | E6: Set to be "Application" | F6: Set to be "Application" | H6: case_reference_list.caseCategory | I6: if case_reference_list.caseCategory = "pre-app" then "pre-application", else "application"
B7: Application classification | C7: Application classification | D7: N/A | E7: Set to be "Major" | F7: Set to be "Non-major" | H7: N/A | I7: N/A - take from S/S
B8: Application type | C8: Application type | D8: Type of application | E8: Type of application | F8: Type of application | H8: basic_data.PermissionSought | I8: Manually check and remapp after
B9: Application subtype | C9: Application subtype | D9: N/A | E9: N/A | F9: N/A | G9: Planning Permission, Listed Building | H9: case_reference_list.caseCategory | I9: if case_reference_list.caseCategory = "listed-building" then "Listed building consent", else "Planning permission"
A10: Dates | B10: Notification received date | C10: Notification received date | D10: Pre-notification date | E10: Pre-notification date | F10: Pre-notification date | H10: N/A | I10: N/A - take from S/S
B11: Expected submission date | C11: Expected application submission date | D11: Expected submission date | E11: Expected submission date (not before) | F11: Expected submission date (not before) | H11: N/A | I11: N/A - take from S/S
B12: Pre-app/Application received date | C12: Pre-app/Application received date | D12: Receipt date | E12: Receipt date | F12: Receipt date | H12: key_dates.DateReceived
B13: Application acknowledged | C13: Application acknowledged | D13: N/A | E13: Letter 7 sent to applicant | F13: Letter 7 sent to applicant | H13: N/A | I13: N/A - take from S/S
B14: Further info requested | C14: Further information requested | D14: N/A | E14: Letter 8 sent to applicant - invalid (if applicable) | F14: Letter 8 sent to applicant - invalid (if applicable) | H14: N/A | I14: N/A - take from S/S
B15: Date agreed for additional info | C15: Date agreed for additional information | D15: N/A | E15: Date agreed for submission of additional docs | F15: Date agreed for submission of additional docs | H15: N/A | I15: N/A - take from S/S
B16: Application valid | C16: Application valid date | D16: N/A | E16: Valid Date | F16: Valid / Validation Date | H16: key_dates.DateValid
B17: Valid letters sent | C17: Valid letters sent | D17: N/A | E17: Valid letters (17 & 9) to LPA and Applicant | F17: Valid letters (17 & 9) to LPA and Applicant | H17: key_dates.ConsultationsWithRelevantAuthoritiesDate
B18: LPA questionnaire sent | C18: LPA questionnaire sent date | D18: N/A | E18: Letter 16 and Q sent to LPA | F18: Letter 16 and Q sent to LPA | H18: key_dates.DateInfoSentToLPA
B19: LPA questionnaire rec'd date | C19: LPA questionnaire received date | D19: N/A | E19: LPA Q received | F19: LPA Q received | G19: Check | H19: key_dates.DateInfoReturnedFromLPA
B20: Target publish date | C20: Target publish date | D20: N/A | E20: Application published due date (valid + 5 working days) | F20: Application published due date (valid + 5 working days) | H20: N/A | I20: N/A - take from S/S
B21: Publish date | C21: Publish date | D21: N/A | E21: Application documents published actual date | F21: Application documents published actual date | H21: key_dates.PublicityForApplicationsDate
B22: Press notice date | C22: Press notice date | D22: N/A | E22: PINS Interested parties press notice placed and TMP ref | F22: PINS Interested parties press notice placed and TMP ref | G22: Extract date | H22: key_dates.NewspaperAdvertDate
B23: Neighbours notified by LPA date | C23: Neighbours notified by LPA date | D23: N/A | E23: LPA Interested parties notification date | F23: LPA Interested parties notification date | H23: key_dates.DateNeighboursNotified
B24: LPA interested parties deadline | C24: LPA interested parties deadline | D24: N/A | E24: LPA Interested parties deadline | F24: LPA Interested parties deadline | H24: N/A | I24: N/A - take from S/S
B25: Site notice by LPA date | C25: Site notice by LPA date | D25: N/A | E25: N/A | F25: N/A | G25: Check | H25: key_dates.SiteNoticeDate
B26: Interested parties press notice deadline | C26: Interested parties press notice deadline | D26: N/A | E26: PINS interested parties press notice deadline | F26: PINS interested parties press notice deadline | H26: N/A | I26: N/A - take from S/S
B27: Mineral Applications date | C27: Mineral Applications | D27: N/A | E27: N/A | F27: N/A | G27: Check | H27: key_dates.MineralNotificationDate
B28: Interim findings date | C28: Interim findings date | D28: N/A | E28: Inspectors Interim findings (letter 25 to applicant) | F28: Inspectors Interim findings (letter 25 to applicant) | H28: N/A | I28: N/A - take from S/S
B29: Representations period - start | C29: Representations period | D29: N/A | E29: Consultations sent | F29: Consultations sent | H29: key_dates.RepresentationPeriodOpen
B30: Representations period - End | C30: Representations period | D30: N/A | E30: Consultations deadline (see Statutory Consultees and Town Parish Council list for list of parties consulted) | F30: Consultations deadline (see Statutory Consultees and Town Parish Council list for list of parties consulted) | H30: key_dates.RepresentationPeriodClose
B31: Reconsultation details sent date | C31: Reconsultation details | D31: N/A | E31: Reconsultation details | F31: Reconsultation details | G31: Extract sent date | H31: N/A | I31: N/A - take from S/S
B32: Reconsultation details deadline date | C32: Reconsultation details | D32: N/A | E32: Reconsultation details | F32: Reconsultation details | G32: Extract deadline date | H32: N/A | I32: N/A - take from S/S
B33: Representations publish date | C33: Representations publish date | D33: N/A | E33: Representations, LPA Questionnaire published date and procedure decision (within 5 days of close of comment period) | F33: Representations, LPA Questionnaire published date and procedure decision (within 5 days of close of comment period) | H33: key_dates.RepresentationsPublishedDate
B34: S106 submitted date | C34: S106 submitted date | D34: N/A | E34: S106 submitted date | F34: S106 submitted date | H34: N/A | I34: N/A - take from S/S
B35: Target decision date | C35: Target decision date | D35: N/A | E35: Target decision date (13 or 16 weeks from valid) | F35: Target decision date (8 weeks from valid) | H35: key_dates.TargetDecisionDate
B36: Extended target decision date | C36: Extended target decision date | D36: N/A | E36: N/A | F36: N/A | H36: key_dates.EoTTargetDate
B37: Recovered date | C37: Recovered date | D37: N/A | E37: N/A | F37: N/A | H37: N/A | I37: Never happened
B38: Site visit type | C38: Site visit type | D38: Site Visit | E38: Inspector USV or ARSV date (if needed) | F38: Inspector USV or ARSV date (if needed) | G38: Extract type | H38: N/A | I38: N/A - take from S/S
B39: Site visit date | C39: Site visit | D39: Site Visit | E39: Inspector USV or ARSV date (if needed) | F39: Inspector USV or ARSV date (if needed) | G39: Extract date | H39: N/A | I39: N/A - take from S/S
A40: Closed status dates | B40: Withdrawn date | C40: Withdrawn date | D40: N/A | E40: N/A | F40: N/A | G40: Process after | H40: N/A | I40: Process after
...

Sheet Sheet3
A2: Case reference | B2: Ref | C2: Ref | D2: Ref | F2: basic_data.CaseReference
A3: Status | B3: N/A | C3: N/A | D3: N/A | F3: N/A
A4: Status | B4: N/A | C4: N/A | D4: N/A | F4: basic_data.Status
A5: Stage | B5: N/A | C5: N/A | D5: N/A | F5: N/A
A6: Application phase | B6: Set to be "Pre-application" | C6: Set to be "Application" | D6: Set to be "Application" | F6: case_reference_list.caseCategory
A7: Application classification | B7: N/A | C7: Set to be "Major" | D7: Set to be "Non-major" | F7: N/A
A8: Application type | B8: Type of application | C8: Type of application | D8: Type of application | F8: basic_data.PermissionSought
A9: Application subtype | B9: N/A | C9: N/A | D9: N/A | E9: Planning Permission, Listed Building | F9: case_reference_list.caseCategory
A10: Notification received date | B10: Pre-notification date | C10: Pre-notification date | D10: Pre-notification date | F10: N/A | G10: Applicant organisation name
A11: Expected application submission date | B11: Expected submission date | C11: Expected submission date (not before) | D11: Expected submission date (not before) | F11: N/A | G11: Agent address
A12: Pre-app/Application received date | B12: Receipt date | C12: Receipt date | D12: Receipt date | F12: key_dates.DateReceived | G12: Applicant address
A13: Application acknowledged | B13: N/A | C13: Letter 7 sent to applicant | D13: Letter 7 sent to applicant | F13: N/A | G13: Agent address
A14: Further information requested | B14: N/A | C14: Letter 8 sent to applicant - invalid (if applicable) | D14: Letter 8 sent to applicant - invalid (if applicable) | F14: N/A | G14: Applicant address
A15: Date agreed for additional information | B15: N/A | C15: Date agreed for submission of additional docs | D15: Date agreed for submission of additional docs | F15: N/A | G15: Agent address
A16: Application valid date | B16: N/A | C16: Valid Date | D16: Valid / Validation Date | F16: key_dates.DateValid | G16: Applicant address
A17: Valid letters sent | B17: N/A | C17: Valid letters (17 & 9) to LPA and Applicant | D17: Valid letters (17 & 9) to LPA and Applicant | F17: key_dates.ConsultationsWithRelevantAuthoritiesDate | G17: Agent address
A18: LPA questionnaire sent date | B18: N/A | C18: Letter 16 and Q sent to LPA | D18: Letter 16 and Q sent to LPA | F18: key_dates.DateInfoSentToLPA | G18: Applicant address
A19: LPA questionnaire received date | B19: N/A | C19: LPA Q received | D19: LPA Q received | E19: Check | F19: key_dates.DateInfoReturnedFromLPA | G19: LPA contact
A20: Target publish date | B20: N/A | C20: Application published due date (valid + 5 working days) | D20: Application published due date (valid + 5 working days) | F20: N/A | G20: Agent address
A21: Publish date | B21: N/A | C21: Application documents published actual date | D21: Application documents published actual date | F21: key_dates.PublicityForApplicationsDate | G21: Applicant address
A22: Press notice date | B22: N/A | C22: PINS Interested parties press notice placed and TMP ref | D22: PINS Interested parties press notice placed and TMP ref | E22: Extract date | F22: key_dates.NewspaperAdvertDate
A23: Neighbours notified by LPA date | B23: N/A | C23: LPA Interested parties notification date | D23: LPA Interested parties notification date | F23: key_dates.DateNeighboursNotified | G23: LPA contact
A24: Neighbours notified by LPA date | B24: N/A | C24: LPA Interested parties notification date | D24: LPA Interested parties notification date | F24: key_dates.DateNeighboursNotified | G24: Agent address
A25: LPA interested parties deadline | B25: N/A | C25: LPA Interested parties deadline | D25: LPA Interested parties deadline | F25: N/A | G25: Applicant address
A26: Site notice by LPA date | B26: N/A | C26: N/A | D26: N/A | E26: Check | F26: key_dates.SiteNoticeDate | G26: Additional contacts
A27: Interested parties press notice deadline | B27: N/A | C27: PINS interested parties press notice deadline | D27: PINS interested parties press notice deadline | F27: N/A | G27: Appointed person / Inspector 1
A28: Mineral Applications | B28: N/A | C28: N/A | D28: N/A | E28: Check | F28: key_dates.MineralNotificationDate | G28: Case officer
A29: Interim findings date | B29: N/A | C29: Inspectors Interim findings (letter 25 to applicant) | D29: Inspectors Interim findings (letter 25 to applicant) | F29: N/A | G29: Date appointed person / inspector appointed
A30: Representations period | B30: N/A | C30: Consultations sent | D30: Consultations sent | F30: key_dates.RepresentationPeriodOpen | G30: LPA contact
A31: Representations period | B31: N/A | C31: Consultations deadline (see Statutory Consultees and Town Parish Council list for list of parties consulted) | D31: Consultations deadline (see Statutory Consultees and Town Parish Council list for list of parties consulted) | F31: key_dates.RepresentationPeriodClose | G31: Agent address
A32: Reconsultation details | B32: N/A | C32: Reconsultation details | D32: Reconsultation details | E32: Extract sent date | F32: N/A | G32: Applicant address
A33: Reconsultation details | B33: N/A | C33: Reconsultation details | D33: Reconsultation details | E33: Extract deadline date | F33: N/A
A34: Representations publish date | B34: N/A | C34: Representations, LPA Questionnaire published date and procedure decision (within 5 days of close of comment period) | D34: Representations, LPA Questionnaire published date and procedure decision (within 5 days of close of comment period) | F34: key_dates.RepresentationsPublishedDate | G34: Agent organisation name
A35: S106 submitted date | B35: N/A | C35: S106 submitted date | D35: S106 submitted date | F35: N/A | G35: Agent address
A36: Target decision date | B36: N/A | C36: Target decision date (13 or 16 weeks from valid) | D36: Target decision date (8 weeks from valid) | F36: key_dates.TargetDecisionDate | G36: Applicant address
A37: Extended target decision date | B37: N/A | C37: N/A | D37: N/A | F37: key_dates.EoTTargetDate | G37: LPA contact
A38: Recovered date | B38: N/A | C38: N/A | D38: N/A | F38: N/A | G38: Agent address
A39: Site visit type | B39: Site Visit | C39: Inspector USV or ARSV date (if needed) | D39: Inspector USV or ARSV date (if needed) | E39: Extract type | F39: N/A | G39: Applicant address
A40: Site visit | B40: Site Visit | C40: Inspector USV or ARSV date (if needed) | D40: Inspector USV or ARSV date (if needed) | E40: Extract date | F40: N/A
A41: Withdrawn date | B41: N/A | C41: N/A | D41: N/A | E41: Process after | F41: N/A | G41: Application phase
...

Sheet case_involvement
A1: TypeOfInvolvement(p) | B1: TypeOfInvolvement(o)
A2: Agent | B2: Case Officer
A3: Inspector | B3: Case Officer
A4: Appointed Person | B4: LPA
A5: Applicant | B5: Applicant
A6: Planning Officer
A7: Previous Inspector
A8: Case Administrator
A9: Case Manager
A10: Case Officer
A11: Legal Officer

Sheet Sheet2
A1: Tab | B1: Column | D1: Tab | E1: Column | G1: Tab | H1: Column
A2: Preapp | B2: Ref | C2: =MATCH(B2,Lookup!D:D,0) -> 2 | D2: Major | E2: Ref | F2: =MATCH(E2,Lookup!E:E,0) -> 2 | G2: Non-major | H2: Ref | I2: =MATCH(H2,Lookup!F:F,0) -> 2
A3: Preapp | B3: Address | C3: =MATCH(B3,Lookup!D:D,0) -> 90 | D3: Major | E3: Address | F3: =MATCH(E3,Lookup!E:E,0) -> 90 | G3: Non-major | H3: Address | I3: =MATCH(H3,Lookup!F:F,0) -> 90
A4: Preapp | B4: LPA | C4: =MATCH(B4,Lookup!D:D,0) -> 45 | D4: Major | E4: LPA | F4: =MATCH(E4,Lookup!E:E,0) -> 45 | G4: Non-major | H4: LPA | I4: =MATCH(H4,Lookup!F:F,0) -> 45
A5: Preapp | B5: Likely issues | C5: =MATCH(B5,Lookup!D:D,0) -> 97 | D5: Major | E5: Likely issues | F5: =MATCH(E5,Lookup!E:E,0) -> 97 | G5: Non-major | H5: Likely Issues | I5: =MATCH(H5,Lookup!F:F,0) -> 97
A6: Preapp | B6: Level & Specialism | C6: =MATCH(B6,Lookup!D:D,0) -> 98 | D6: Major | E6: Level & Specialism | F6: =MATCH(E6,Lookup!E:E,0) -> 98 | G6: Non-major | H6: Level & Specialism | I6: =MATCH(H6,Lookup!F:F,0) -> 98
A7: Preapp | B7: Applicant | C7: =MATCH(B7,Lookup!D:D,0) -> 66 | D7: Major | E7: Applicant | F7: =MATCH(E7,Lookup!E:E,0) -> 66 | G7: Non-major | H7: Applicant | I7: =MATCH(H7,Lookup!F:F,0) -> 66
A8: Preapp | B8: Agent | C8: =MATCH(B8,Lookup!D:D,0) -> 55 | D8: Major | E8: Agent | F8: =MATCH(E8,Lookup!E:E,0) -> 55 | G8: Non-major | H8: Agent | I8: =MATCH(H8,Lookup!F:F,0) -> 55
A9: Preapp | B9: Type of application | C9: =MATCH(B9,Lookup!D:D,0) -> 8 | D9: Major | E9: Type of application | F9: =MATCH(E9,Lookup!E:E,0) -> 8 | G9: Non-major | H9: Type of application | I9: =MATCH(H9,Lookup!F:F,0) -> 8
A10: Preapp | B10: Pre-notification date | C10: =MATCH(B10,Lookup!D:D,0) -> 10 | D10: Major | E10: Pre-application advice? | F10: =MATCH(E10,Lookup!E:E,0) -> 42 | G10: Non-major | H10: Pre-application advice? | I10: =MATCH(H10,Lookup!F:F,0) -> 42
A11: Preapp | B11: Expected submission date | C11: =MATCH(B11,Lookup!D:D,0) -> 11 | D11: Major | E11: Pre-application reference | F11: =MATCH(E11,Lookup!E:E,0) -> 44 | G11: Non-major | H11: Pre-application reference | I11: =MATCH(H11,Lookup!F:F,0) -> 44
A12: Preapp | B12: Receipt date | C12: =MATCH(B12,Lookup!D:D,0) -> 12 | D12: Major | E12: Estimated fee | F12: =MATCH(E12,Lookup!E:E,0) -> 188 | G12: Non-major | H12: Estimated fee | I12: =MATCH(H12,Lookup!F:F,0) -> 188
A13: Preapp | B13: Development | C13: =MATCH(B13,Lookup!D:D,0) -> 96 | D13: Major | E13: Pre-notification date | F13: =MATCH(E13,Lookup!E:E,0) -> 10 | G13: Non-major | H13: Pre-notification date | I13: =MATCH(H13,Lookup!F:F,0) -> 10
... A28: Preapp | B28: Amount Invoiced | C28: =MATCH(B28,Lookup!D:D,0) -> 127 | D28: Major | E28: Valid Date | F28: =MATCH(E28,Lookup!E:E,0) -> 16 | G28: Non-major | H28: Any confidential docs? | I28: =MATCH(H28,Lookup!F:F,0) -> 198
D29: Major | E29: Application published due date (valid + 5 working days) | F29: =MATCH(E29,Lookup!E:E,0) -> 20 | G29: Non-major | H29: Application documents published actual date | I29: =MATCH(H29,Lookup!F:F,0) -> 21
D30: Major | E30: Any confidential docs? | F30: =MATCH(E30,Lookup!E:E,0) -> 198 | G30: Non-major | H30: Valid letters (17 & 9) to LPA and Applicant | I30: =MATCH(H30,Lookup!F:F,0) -> 17
D31: Major | E31: Application documents published actual date | F31: =MATCH(E31,Lookup!E:E,0) -> 21 | G31: Non-major | H31: LPA Q received | I31: =MATCH(H31,Lookup!F:F,0) -> 19
D32: Major | E32: Valid letters (17 & 9) to LPA and Applicant | F32: =MATCH(E32,Lookup!E:E,0) -> 17 | G32: Non-major | H32: LPA CIL response | I32: =MATCH(H32,Lookup!F:F,0) -> 107
D33: Major | E33: LPA Q received | F33: =MATCH(E33,Lookup!E:E,0) -> 19 | G33: Non-major | H33: CIL amount | I33: =MATCH(H33,Lookup!F:F,0) -> 108
D34: Major | E34: LPA CIL response | F34: =MATCH(E34,Lookup!E:E,0) -> 107 | G34: Non-major | H34: EIA - screening request sent to EST (confirm with EST when application valid) | I34: =MATCH(H34,Lookup!F:F,0) -> 110
D35: Major | E35: EIA - screening request sent to EST (confirm with EST when application valid) | F35: =MATCH(E35,Lookup!E:E,0) -> 110 | G35: Non-major | H35: EIA outcome (publish any letter to gov.uk) | I35: =MATCH(H35,Lookup!F:F,0) -> 111
D36: Major | E36: EIA outcome (publish any letter to gov.uk) | F36: =MATCH(E36,Lookup!E:E,0) -> 111 | G36: Non-major | H36: Consultations sent | I36: =MATCH(H36,Lookup!F:F,0) -> 29
D37: Major | E37: Consultations sent | F37: =MATCH(E37,Lookup!E:E,0) -> 29 | G37: Non-major | H37: Consultations deadline (see Statutory Consultees and Town Parish Council list for list of parties consulted) | I37: =MATCH(H37,Lookup!F:F,0) -> 30
D38: Major | E38: Consultations deadline (see Statutory Consultees and Town Parish Council list for list of parties consulted) | F38: =MATCH(E38,Lookup!E:E,0) -> 30 | G38: Non-major | H38: LPA Interested parties notification date | I38: =MATCH(H38,Lookup!F:F,0) -> 23
D39: Major | E39: LPA Interested parties notification date | F39: =MATCH(E39,Lookup!E:E,0) -> 23 | G39: Non-major | H39: LPA Interested parties deadline | I39: =MATCH(H39,Lookup!F:F,0) -> 24
D40: Major | E40: LPA Interested parties deadline | F40: =MATCH(E40,Lookup!E:E,0) -> 24 | G40: Non-major | H40: PINS Interested parties press notice placed and TMP ref | I40: =MATCH(H40,Lookup!F:F,0) -> 22
... D58: Major | E58: Grant/Refuse | F58: =MATCH(E58,Lookup!E:E,0) -> 138 | G58: Non-major | H58: Comments/Notes | I58: =MATCH(H58,Lookup!F:F,0) -> 142
D59: Major | E59: Time taken from valid to decision | F59: =MATCH(E59,Lookup!E:E,0) -> 195
D60: Major | E60: Comments/Notes | F60: =MATCH(E60,Lookup!E:E,0) -> 142

Sheet Sheet1
A1: Template LEGACY cases S62A | C1: Horizon | D1: Notes
B2: Case reference | C2: Case reference
A3: Case progress | B3: Pre-application status | D3: New column, need to find horizon equivalent if it does come from there
B4: Application Status
B5: Stage | D5: Need to establish column in horizon
A6: Case type | B6: Application phase
B7: Application classification
B8: Application type
B9: Application subtype
A10: Dates | B10: Notification received date
B11: Expected submission date
B12: Pre-app/Application received date
B13: Application acknowledged
B14: Further info requested
B15: Date agreed for additional info
B16: Application valid
B17: Valid letters sent
B18: LPA questionnaire sent
B19: LPA questionnaire rec'd date
B20: Target publish date
B21: Publish date
B22: Press notice date
... B40: Site visit date
A41: Closed status dates | B41: Withdrawn date
B42: Turned away date
A43: Pre-application details | B43: Pre-application advice requested
B44: Pre-app received date
B45: Pre-app reference
A46: LPA | B46: LPA
B47: LPA contact - First name
B48: LPA contact - Last name
B49: LPA contact - Phone number
B50: LPA contact - Email
A51: Secondary LPA | B51: Secondary LPA
B52: Secondary LPA - First name
B53: Secondary LPA - Last name
B54: Secondary LPA - Phone number
B55: Secondary LPA - Email
A56: Agent | B56: Agent organisation name
B57: Agent address 1
...
