Workbook

Sheet Lookup
A1: Template LEGACY cases S62A | C1: Pre-application - DONE | D1: Application (Major) | E1: Application (Non Major) | F1: Horizon | G1: Notes
B2: Case reference | C2: Ref | D2: Ref | E2: Ref
A3: Case progress | B3: Pre-application status | C3: N/A | D3: N/A | E3: N/A
B4: Application Status | C4: N/A | D4: N/A | E4: N/A
B5: Stage | C5: N/A | D5: N/A | E5: N/A
A6: Case type | B6: Pre-application or application | C6: Set to be "pre-application" | D6: Set to be "application" | E6: Set to be "application"
B7: Application classification | C7: N/A | D7: Set to be "Major" | E7: Set to be "Non-major"
B8: Application type | C8: Type of application | D8: Type of application | E8: Type of application
B9: Application subtype | C9: N/A | D9: N/A | E9: N/A | G9: Planning Permission, Listed Building
A10: Dates | B10: Notification received date | C10: Pre-notification date | D10: Pre-notification date | E10: Pre-notification date
B11: Expected submission date | C11: Expected submission date | D11: Expected submission date (not before) | E11: Expected submission date (not before)
B12: Pre-app/Application received date | C12: Receipt date | D12: Receipt date | E12: Receipt date
B13: Application acknowledged | C13: N/A | D13: Letter 7 sent to applicant | E13: Letter 7 sent to applicant
B14: Further info requested | C14: N/A | D14: Letter 8 sent to applicant - invalid (if applicable) | E14: Letter 8 sent to applicant - invalid (if applicable)
B15: Date agreed for additional info | C15: N/A | D15: Date agreed for submission of additional docs | E15: Date agreed for submission of additional docs
B16: Application valid | C16: N/A | D16: Valid Date | E16: Valid / Validation Date
B17: Valid letters sent | C17: N/A | D17: Valid letters (17 & 9) to LPA and Applicant | E17: Valid letters (17 & 9) to LPA and Applicant
B18: LPA questionnaire sent | C18: N/A | D18: Letter 16 and Q sent to LPA | E18: Letter 16 and Q sent to LPA
B19: LPA questionnaire rec'd date | C19: N/A | D19: LPA Q received | E19: LPA Q received | G19: Check
B20: Target publish date | C20: N/A | D20: Application published due date (valid + 5 working days) | E20: Application published due date (valid + 5 working days)
B21: Publish date | C21: N/A | D21: Application documents published actual date | E21: Application documents published actual date
B22: Press notice date | C22: N/A | D22: PINS Interested parties press notice placed and TMP ref | E22: PINS Interested parties press notice placed and TMP ref | G22: Extract date
B23: Neighbours notified by LPA date | C23: N/A | D23: LPA Interested parties notification date | E23: LPA Interested parties notification date
B24: Neighbours notified by LPA date | C24: N/A | D24: LPA Interested parties notification date | E24: LPA Interested parties notification date
B25: LPA interested parties deadline | C25: N/A | D25: LPA Interested parties deadline | E25: LPA Interested parties deadline
B26: Site notice by LPA date | C26: N/A | D26: N/A | E26: N/A | G26: Check
B27: Interested parties press notice deadline | C27: N/A | D27: PINS interested parties press notice deadline | E27: PINS interested parties press notice deadline
B28: Mineral Applications date | C28: N/A | D28: N/A | E28: N/A | G28: Check
B29: Interim findings date | C29: N/A | D29: Inspectors Interim findings (letter 25 to applicant) | E29: Inspectors Interim findings (letter 25 to applicant)
B30: Representations period - start | C30: N/A | D30: Consultations sent | E30: Consultations sent
B31: Representations period - End | C31: N/A | D31: Consultations deadline (see Statutory Consultees and Town Parish Council list for list of parties consulted) | E31: Consultations deadline (see Statutory Consultees and Town Parish Council list for list of parties consulted)
B32: Reconsultation details sent date | C32: N/A | D32: Reconsultation details | E32: Reconsultation details | G32: Extract sent date
B33: Reconsultation details deadline date | C33: N/A | D33: Reconsultation details | E33: Reconsultation details | G33: Extract deadline date
B34: Representations publish date | C34: N/A | D34: Representations, LPA Questionnaire published date and procedure decision (within 5 days of close of comment period) | E34: Representations, LPA Questionnaire published date and procedure decision (within 5 days of close of comment period)
B35: S106 submitted date | C35: N/A | D35: S106 submitted date | E35: S106 submitted date
B36: Target decision date | C36: N/A | D36: Target decision date (13 or 16 weeks from valid) | E36: Target decision date (8 weeks from valid)
B37: Extended target decision date | C37: N/A | D37: N/A | E37: N/A
B38: Recovered date | C38: N/A | D38: N/A | E38: N/A
B39: Site visit type | C39: Site Visit | D39: Inspector USV or ARSV date (if needed) | E39: Inspector USV or ARSV date (if needed) | G39: Extract type
B40: Site visit date | C40: Site Visit | D40: Inspector USV or ARSV date (if needed) | E40: Inspector USV or ARSV date (if needed) | G40: Extract date
...

Sheet Sheet2
A1: Tab | B1: Column | D1: Tab | E1: Column | G1: Tab | H1: Column
A2: Preapp | B2: Ref | C2: =MATCH(B2,Lookup!C:C,0) -> 2 | D2: Major | E2: Ref | F2: =MATCH(E2,Lookup!D:D,0) -> 2 | G2: Non-major | H2: Ref | I2: =MATCH(H2,Lookup!E:E,0) -> 2
A3: Preapp | B3: Address | C3: =MATCH(B3,Lookup!C:C,0) -> 87 | D3: Major | E3: Address | F3: =MATCH(E3,Lookup!D:D,0) -> 87 | G3: Non-major | H3: Address | I3: =MATCH(H3,Lookup!E:E,0) -> 87
A4: Preapp | B4: LPA | C4: =MATCH(B4,Lookup!C:C,0) -> 46 | D4: Major | E4: LPA | F4: =MATCH(E4,Lookup!D:D,0) -> 46 | G4: Non-major | H4: LPA | I4: =MATCH(H4,Lookup!E:E,0) -> 46
A5: Preapp | B5: Likely issues | C5: =MATCH(B5,Lookup!C:C,0) -> 97 | D5: Major | E5: Likely issues | F5: =MATCH(E5,Lookup!D:D,0) -> 97 | G5: Non-major | H5: Likely Issues | I5: =MATCH(H5,Lookup!E:E,0) -> 97
A6: Preapp | B6: Level & Specialism | C6: =MATCH(B6,Lookup!C:C,0) -> 98 | D6: Major | E6: Level & Specialism | F6: =MATCH(E6,Lookup!D:D,0) -> 98 | G6: Non-major | H6: Level & Specialism | I6: =MATCH(H6,Lookup!E:E,0) -> 98
A7: Preapp | B7: Applicant | C7: =MATCH(B7,Lookup!C:C,0) -> 67 | D7: Major | E7: Applicant | F7: =MATCH(E7,Lookup!D:D,0) -> 67 | G7: Non-major | H7: Applicant | I7: =MATCH(H7,Lookup!E:E,0) -> 67
A8: Preapp | B8: Agent | C8: =MATCH(B8,Lookup!C:C,0) -> 56 | D8: Major | E8: Agent | F8: =MATCH(E8,Lookup!D:D,0) -> 56 | G8: Non-major | H8: Agent | I8: =MATCH(H8,Lookup!E:E,0) -> 56
A9: Preapp | B9: Type of application | C9: =MATCH(B9,Lookup!C:C,0) -> 8 | D9: Major | E9: Type of application | F9: =MATCH(E9,Lookup!D:D,0) -> 8 | G9: Non-major | H9: Type of application | I9: =MATCH(H9,Lookup!E:E,0) -> 8
A10: Preapp | B10: Pre-notification date | C10: =MATCH(B10,Lookup!C:C,0) -> 10 | D10: Major | E10: Pre-application advice? | F10: =MATCH(E10,Lookup!D:D,0) -> 43 | G10: Non-major | H10: Pre-application advice? | I10: =MATCH(H10,Lookup!E:E,0) -> 43
A11: Preapp | B11: Expected submission date | C11: =MATCH(B11,Lookup!C:C,0) -> 11 | D11: Major | E11: Pre-application reference | F11: =MATCH(E11,Lookup!D:D,0) -> 45 | G11: Non-major | H11: Pre-application reference | I11: =MATCH(H11,Lookup!E:E,0) -> 45
A12: Preapp | B12: Receipt date | C12: =MATCH(B12,Lookup!C:C,0) -> 12 | D12: Major | E12: Estimated fee | F12: =MATCH(E12,Lookup!D:D,0) -> 188 | G12: Non-major | H12: Estimated fee | I12: =MATCH(H12,Lookup!E:E,0) -> 188
A13: Preapp | B13: Development | C13: =MATCH(B13,Lookup!C:C,0) -> 96 | D13: Major | E13: Pre-notification date | F13: =MATCH(E13,Lookup!D:D,0) -> 10 | G13: Non-major | H13: Pre-notification date | I13: =MATCH(H13,Lookup!E:E,0) -> 10
... A28: Preapp | B28: Amount Invoiced | C28: =MATCH(B28,Lookup!C:C,0) -> 127 | D28: Major | E28: Valid Date | F28: =MATCH(E28,Lookup!D:D,0) -> 16 | G28: Non-major | H28: Any confidential docs? | I28: =MATCH(H28,Lookup!E:E,0) -> 198
D29: Major | E29: Application published due date (valid + 5 working days) | F29: =MATCH(E29,Lookup!D:D,0) -> 20 | G29: Non-major | H29: Application documents published actual date | I29: =MATCH(H29,Lookup!E:E,0) -> 21
D30: Major | E30: Any confidential docs? | F30: =MATCH(E30,Lookup!D:D,0) -> 198 | G30: Non-major | H30: Valid letters (17 & 9) to LPA and Applicant | I30: =MATCH(H30,Lookup!E:E,0) -> 17
D31: Major | E31: Application documents published actual date | F31: =MATCH(E31,Lookup!D:D,0) -> 21 | G31: Non-major | H31: LPA Q received | I31: =MATCH(H31,Lookup!E:E,0) -> 19
D32: Major | E32: Valid letters (17 & 9) to LPA and Applicant | F32: =MATCH(E32,Lookup!D:D,0) -> 17 | G32: Non-major | H32: LPA CIL response | I32: =MATCH(H32,Lookup!E:E,0) -> 107
D33: Major | E33: LPA Q received | F33: =MATCH(E33,Lookup!D:D,0) -> 19 | G33: Non-major | H33: CIL amount | I33: =MATCH(H33,Lookup!E:E,0) -> 108
D34: Major | E34: LPA CIL response | F34: =MATCH(E34,Lookup!D:D,0) -> 107 | G34: Non-major | H34: EIA - screening request sent to EST (confirm with EST when application valid) | I34: =MATCH(H34,Lookup!E:E,0) -> 110
D35: Major | E35: EIA - screening request sent to EST (confirm with EST when application valid) | F35: =MATCH(E35,Lookup!D:D,0) -> 110 | G35: Non-major | H35: EIA outcome (publish any letter to gov.uk) | I35: =MATCH(H35,Lookup!E:E,0) -> 111
D36: Major | E36: EIA outcome (publish any letter to gov.uk) | F36: =MATCH(E36,Lookup!D:D,0) -> 111 | G36: Non-major | H36: Consultations sent | I36: =MATCH(H36,Lookup!E:E,0) -> 30
D37: Major | E37: Consultations sent | F37: =MATCH(E37,Lookup!D:D,0) -> 30 | G37: Non-major | H37: Consultations deadline (see Statutory Consultees and Town Parish Council list for list of parties consulted) | I37: =MATCH(H37,Lookup!E:E,0) -> 31
D38: Major | E38: Consultations deadline (see Statutory Consultees and Town Parish Council list for list of parties consulted) | F38: =MATCH(E38,Lookup!D:D,0) -> 31 | G38: Non-major | H38: LPA Interested parties notification date | I38: =MATCH(H38,Lookup!E:E,0) -> 23
D39: Major | E39: LPA Interested parties notification date | F39: =MATCH(E39,Lookup!D:D,0) -> 23 | G39: Non-major | H39: LPA Interested parties deadline | I39: =MATCH(H39,Lookup!E:E,0) -> 25
D40: Major | E40: LPA Interested parties deadline | F40: =MATCH(E40,Lookup!D:D,0) -> 25 | G40: Non-major | H40: PINS Interested parties press notice placed and TMP ref | I40: =MATCH(H40,Lookup!E:E,0) -> 22
... D58: Major | E58: Grant/Refuse | F58: =MATCH(E58,Lookup!D:D,0) -> 138 | G58: Non-major | H58: Comments/Notes | I58: =MATCH(H58,Lookup!E:E,0) -> 142
D59: Major | E59: Time taken from valid to decision | F59: =MATCH(E59,Lookup!D:D,0) -> 195
D60: Major | E60: Comments/Notes | F60: =MATCH(E60,Lookup!D:D,0) -> 142
